Workbook

Sheet 通过
A1: 序号 | B1: 省份 | C1: 数量 | D1: 畜种 | E1: 单位名称
A2: 1 | B2: 天津 | C2: 1 | D2: 生猪 | E2: 天津市宁河原种猪场
A3: 2 | B3: 河北 | C3: 1 | D3: 生猪 | E3: 中粮家佳康（张北）有限公司
A4: 3 | C4: 2 | D4: 生猪 | E4: 河北省永清县远村畜业养殖基地
A5: 4 | C5: 3 | D5: 生猪 | E5: 昌黎县天惠农业科技有限公司
A6: 5 | C6: 4 | D6: 蛋鸡 | E6: 北粮农业股份有限公司
A7: 6 | C7: 5 | D7: 蛋鸡 | E7: 平山县西柏坡五丰蛋鸡养殖专业合作社
A8: 7 | C8: 6 | D8: 蛋鸡 | E8: 涉县华裕家禽育种有限公司
A9: 8 | C9: 7 | D9: 奶牛 | E9: 保定双丰牧业有限公司
A10: 9 | C10: 8 | D10: 奶牛 | E10: 河北首农现代农业科技有限公司
A11: 10 | C11: 9 | D11: 奶牛 | E11: 承德华商恒益农业开发有限公司
A12: 11 | C12: 10 | D12: 肉羊 | E12: 河北欣苑农业开发股份有限公司
A13: 12 | B13: 山西 | C13: 1 | D13: 生猪 | E13: 高平市神农永兴食品有限责任公司
A14: 13 | C14: 2 | D14: 生猪 | E14: 山西南山百世食安农牧业有限公司
A15: 14 | C15: 3 | D15: 肉鸡 | E15: 晋中市金尚牧业开发有限公司
A16: 15 | C16: 4 | D16: 蛋鸡 | E16: 山西晋龙养殖股份有限公司
A17: 16 | C17: 5 | D17: 奶牛 | E17: 山西仁德牧业有限责任公司
A18: 17 | C18: 6 | D18: 奶牛 | E18: 大同市南郊区四方高科农牧有限公司
A19: 18 | B19: 内蒙古 | C19: 1 | D19: 奶牛 | E19: 巴彦淖尔市圣牧盘古牧业有限责任公司
A20: 19 | C20: 2 | D20: 奶牛 | E20: 内蒙古富源牧业（托县）有限责任公司
A21: 20 | C21: 3 | D21: 肉牛 | E21: 通辽市洪泰农业发展有限公司
A22: 21 | C22: 4 | D22: 肉羊 | E22: 内蒙古富川养殖科技股份有限公司
A23: 22 | C23: 5 | D23: 种羊 | E23: 内蒙古乐科生物技术有限公司
A24: 23 | C24: 6 | D24: 驴 | E24: 内蒙古草原同源牧业有限公司
A25: 24 | B25: 辽宁 | C25: 1 | D25: 生猪 | E25: 朝阳广硕牧业有限公司
A26: 25 | C26: 2 | D26: 蛋鸡 | E26: 沈阳华美畜禽有限公司
A27: 26 | C27: 3 | D27: 肉鸡 | E27: 丹东耘垦养殖有限公司
A28: 27 | C28: 4 | D28: 肉鸡 | E28: 北票市宏发食品有限公司(东官黄古屯肉鸡养殖扶贫农场)
A29: 28 | B29: 大连 | C29: 1 | D29: 蛋鸡 | E29: 大连韩伟养鸡有限公司旅顺分司
A30: 29 | B30: 吉林 | C30: 1 | D30: 生猪 | E30: 吉林省德兴探感食品有限公司
A31: 30 | C31: 2 | D31: 生猪 | E31: 吉林省远鸣牧业股份有限公司
A32: 31 | C32: 3 | D32: 肉牛 | E32: 延边东盛黄牛资源保种有限公司
A33: 32 | B33: 江苏 | C33: 1 | D33: 生猪 | E33: 江苏加华种猪有限公司
A34: 33 | C34: 2 | D34: 生猪 | E34: 江苏高策农牧科技有限公司
A35: 34 | C35: 3 | D35: 生猪 | E35: 连云港北欧农庄生猪养殖有限公司
A36: 35 | C36: 4 | D36: 生猪 | E36: 邳州正大食品有限公司(岔河育成猪项目一场)
A37: 36 | C37: 5 | D37: 肉鸭（番鸭） | E37: 淮安温氏畜牧有限公司
A38: 37 | B38: 浙江 | C38: 1 | D38: 生猪 | E38: 浙江灯塔种猪有限公司
A39: 38 | C39: 2 | D39: 生猪 | E39: 浙江武义绿驰农业开发有限公司
A40: 39 | C40: 3 | D40: 蛋鸡 | E40: 慈溪市新浦益大养鸡场
...

Sheet 不通过
A1: 2018年畜禽养殖标准化示范场不通过名单
A2: 序号 | B2: 省份 | C2: 数量 | D2: 畜种 | E2: 单位名称 | F2: 评审意见
A3: 1 | B3: 辽宁 | C3: 1 | D3: 生猪 | E3: 北镇大北农农牧食品有限公司 | F3: 重大动物疫病防控和安全生产能力有限
A4: 2 | C4: 2 | D4: 肉牛 | E4: 凌源市牧兴农业开发有限公司 | F4: 未提供该企业的目前生产规模、生产性能水平数据等，管理和考核制度不全。
A5: 3 | B5: 江西 | C5: 1 | D5: 生猪 | E5: 江西曾鑫生态养殖有限公司 | F5: 规模较小，集约化和良种化程度低，质量安全追溯体系有待完善。
A6: 4 | B6: 青岛 | C6: 1 | D6: 生猪 | E6: 青岛达生泽六畜牧有限公司 | F6: 申请材料简单，缺少现场考核结论等支撑材料。猪舍设计和建设陈旧，设施化程度低，质量安全追溯体系有待完善。
A7: 5 | B7: 河南 | C7: 1 | D7: 蛋鸡 | E7: 新乡市长寿蛋业有限公司 | F7: 现场考核场区环境差，病死畜禽无害化处理不够规范，信息化管理水平较低
A8: 6 | C8: 2 | D8: 蛋鸡 | E8: 鹤壁市绿洲牧业有限公司 | F8: 未见各种档案记录
A9: 7 | B9: 广东 | C9: 1 | D9: 蛋鸡 | E9: 台山市赛科农业技术有限公司 | F9: 资料不清晰 ，已有和在建规模不清楚，平面图看不清厂区布局；胚蛋生产场不应在申报之列，没有生产性能数据
A10: 8 | B10: 海南 | C10: 1 | D10: 生猪 | E10: 儋州鑫棠牧业有限公司 | F10: 申报材料不全，在养殖设施化、智能化方面存在不足，场区环境达不到标准，管理制度建设和信息化上不健全。
A11: 9 | B11: 贵州 | C11: 1 | D11: 生猪 | E11: 贵州黔农农业科技有限公司 | F11: 生产规模及集约化、设施化、智能化等硬件建设存在不足；管理上，制度建设和信息化不健全
A12: 10 | B12: 青海 | C12: 1 | D12: 肉牛、奶牛 | E12: 海晏高原藏区牦牛养殖专业合作社 | F12: 申请材料陈旧，未提供该企业目前生产规模、生产性能水平数据等。
A13: 11 | B13: 新疆 | C13: 1 | D13: 奶牛 | E13: 昌吉市正飞牛业养殖有限责任公司 | F13: 缺少现场考核结果，管理和考核制度不全，生产水平有待提升。

Sheet 评审结果
A1: 2018年畜禽养殖标准化示范场名单
A2: 省份 | B2: 数量 | C2: 畜种 | D2: 单位名称 | E2: 评审结果
A3: 天津 | B3: 1 | C3: 生猪 | D3: 天津市宁河原种猪场 | E3: =VLOOKUP(D3,[1]投票表汇总!$D$2:$H$118,5,0) -> 通过
A4: 河北 | B4: 1 | C4: 生猪 | D4: 中粮家佳康（张北）有限公司 | E4: =VLOOKUP(D4,[1]投票表汇总!$D$2:$H$118,5,0) -> 通过
A5: 河北 | B5: 2 | C5: 生猪 | D5: 河北省永清县远村畜业养殖基地 | E5: =VLOOKUP(D5,[1]投票表汇总!$D$2:$H$118,5,0) -> 通过
A6: 河北 | B6: 3 | C6: 生猪 | D6: 昌黎县天惠农业科技有限公司 | E6: =VLOOKUP(D6,[1]投票表汇总!$D$2:$H$118,5,0) -> 通过
A7: 河北 | B7: 4 | C7: 蛋鸡 | D7: 北粮农业股份有限公司 | E7: =VLOOKUP(D7,[1]投票表汇总!$D$2:$H$118,5,0) -> 通过
A8: 河北 | B8: 5 | C8: 蛋鸡 | D8: 平山县西柏坡五丰蛋鸡养殖专业合作社 | E8: =VLOOKUP(D8,[1]投票表汇总!$D$2:$H$118,5,0) -> 通过
A9: 河北 | B9: 6 | C9: 蛋鸡 | D9: 涉县华裕家禽育种有限公司 | E9: =VLOOKUP(D9,[1]投票表汇总!$D$2:$H$118,5,0) -> 通过
A10: 河北 | B10: 7 | C10: 奶牛 | D10: 保定双丰牧业有限公司 | E10: =VLOOKUP(D10,[1]投票表汇总!$D$2:$H$118,5,0) -> 通过
A11: 河北 | B11: 8 | C11: 奶牛 | D11: 河北首农现代农业科技有限公司 | E11: =VLOOKUP(D11,[1]投票表汇总!$D$2:$H$118,5,0) -> 通过
A12: 河北 | B12: 9 | C12: 奶牛 | D12: 承德华商恒益农业开发有限公司 | E12: =VLOOKUP(D12,[1]投票表汇总!$D$2:$H$118,5,0) -> 通过
A13: 河北 | B13: 10 | C13: 肉羊 | D13: 河北欣苑农业开发股份有限公司 | E13: =VLOOKUP(D13,[1]投票表汇总!$D$2:$H$118,5,0) -> 通过
A14: 山西 | B14: 1 | C14: 生猪 | D14: 高平市神农永兴食品有限责任公司 | E14: =VLOOKUP(D14,[1]投票表汇总!$D$2:$H$118,5,0) -> 通过
... A118: 黑龙江农垦 | B118: 1 | C118: 奶牛 | D118: 北安农垦金澳牧场专业合作社 | E118: =VLOOKUP(D118,[1]投票表汇总!$D$2:$H$118,5,0) -> 通过
